Exception in thread Thread-160:
Traceback (most recent call last):
  File "/usr/lib/python2.7/threading.py", line 810, in __bootstrap_inner
    self.run()
  File "/usr/lib/python2.7/threading.py", line 1082, in run
    self.function(*self.args, **self.kwargs)
  File "/home/user/smtp_sec/imap_sec.py", line 210, in timed_imap_exchange
    self.push_up_next_message()
  File "/home/user/smtp_sec/imap_sec.py", line 220, in push_up_next_message
    folder, uid, False)
  File "/home/user/smtp_sec/imap_sec.py", line 263, in add_message_to_folder_internal
    self.save_index(self.mapping)
  File "/home/user/smtp_sec/imap_sec.py", line 155, in save_index
    self.append_index(table)
  File "/home/user/smtp_sec/imap_sec.py", line 139, in append_index
    typ, data = imaplib.IMAP4_SSL.append(self, CRYPTOBLOBS, None, None, str(message))
  File "/usr/lib/python2.7/imaplib.py", line 336, in append
    return self._simple_command(name, mailbox, flags, date_time)
  File "/usr/lib/python2.7/imaplib.py", line 1087, in _simple_command
    return self._command_complete(name, self._command(name, *args))
  File "/usr/lib/python2.7/imaplib.py", line 909, in _command_complete
    typ, data = self._get_tagged_response(tag)
  File "/home/user/smtp_sec/imap_sec.py", line 406, in _get_tagged_response
    a = imaplib.IMAP4_SSL._get_tagged_response(self, tag)
  File "/usr/lib/python2.7/imaplib.py", line 1016, in _get_tagged_response
    self._get_response()
  File "/usr/lib/python2.7/imaplib.py", line 928, in _get_response
    resp = self._get_line()
  File "/usr/lib/python2.7/imaplib.py", line 1026, in _get_line
    line = self.readline()
  File "/home/user/smtp_sec/imap_sec.py", line 411, in readline
    a = imaplib.IMAP4_SSL.readline(self)
  File "/usr/lib/python2.7/imaplib.py", line 1188, in readline
    return self.file.readline()
  File "/usr/lib/python2.7/socket.py", line 447, in readline
    data = self._sock.recv(self._rbufsize)
  File "/usr/lib/python2.7/ssl.py", line 709, in recv
    return self.read(buflen)
  File "/usr/lib/python2.7/ssl.py", line 603, in read
    v = self._sslobj.read(len or 1024)
SSLError: [SSL: WRONG_VERSION_NUMBER] wrong version number (_ssl.c:1750)
